Workbook
Name _DLX1.USE: #REF!
Name _Regression_Int: 1
Name a: #REF!
Name aa: #REF!
Name aaa: INDEX(#REF!,COUNTA(#REF!)-#REF!+1):INDEX(#REF!,COUNTA(#REF!))
Name ac: #REF!
Name asdfasdfasdfasdfasdfasdf: INDEX(#REF!,COUNTA(#REF!)-#REF!+1):INDEX(#REF!,COUNTA(#REF!))
Name b: #REF!
Name BHYDailyYield: OFFSET(#REF!,COUNTA(#REF!)-1,0,-254,1)
Name BLoansDailyYield: OFFSET(#REF!,COUNTA(#REF!)-1,0,-254,1)
Name Bond_Swap_Date: OFFSET(#REF!,COUNTA(#REF!)-1,0,-96,1)
Name Bond_Swap_Worst: OFFSET(#REF!,COUNTA(#REF!)-1,0,-96,1)
Name BR: #REF!
Name Business_Stat_Hist: OFFSET(#REF!,0,0,COUNTA(#REF!),5)
Name Ccy: #REF!
Name Chart_2: #REF!
Name CHART_9a: #REF!
Name CHART1: #REF!
Name CHART10: #REF!
Name Chart100: #REF!
Name chart11: #REF!
Name CHART12: #REF!
Name CHART13: #REF!
Name CHART14: #REF!
Name CHART15: #REF!
Name CHART16: #REF!
Name CHART2: #REF!
Name Chart2x: INDEX(#REF!,COUNTA(#REF!)-#REF!+1):INDEX(#REF!,COUNTA(#REF!))
Name CHART3: #REF!
Name Chart3x: #N/A
Name CHART4: #REF!
Name CHART5: #REF!
Name CHART6: #REF!
Name CHART7: #REF!
Name CHART8: #REF!
Name CHART9: #REF!
Name CHART9a: #REF!
Name clean_spreads: #REF!
Name CLPercent: INDEX(#REF!,COUNTA(#REF!)-#REF!+1):INDEX(#REF!,COUNTA(#REF!))
Name CLpercentYR: INDEX(#REF!,COUNTA(#REF!)-#REF!+1):INDEX(#REF!,COUNTA(#REF!))
Name CLQTR: #REF!
Name CLVolMN: #REF!
Name CLVolume: INDEX(#REF!,COUNTA(#REF!)-#REF!+1):INDEX(#REF!,COUNTA(#REF!))
Name CLVolumeYR: INDEX(#REF!,COUNTA(#REF!)-#REF!+1):INDEX(#REF!,COUNTA(#REF!))
Name CommercialExAIGMetrics: #REF!
Name Copyright: #REF!
Name CopyrightAnalytics: #REF!
Name CreatedFor: #REF!
Name CreatedForTitle: #REF!
Name CS_ALL: OFFSET(#REF!, COUNTA(#REF!)-1,0,-13,1)
Name CS_LBO: OFFSET(#REF!, COUNTA(#REF!)-1,0,-13,1)
Name CS_MA: OFFSET(#REF!, COUNTA(#REF!)-1,0,-13,1)
Name CS_Period: OFFSET(#REF!, COUNTA(#REF!)-1,0,-13,1)
Name Currency_Table: OFFSET(#REF!,0,0,COUNTA(#REF!)-1,5)
Name Currency_Table2: OFFSET(#REF!,0,0,COUNTA(#REF!)-1,5)
Name Currency_Table3: OFFSET(#REF!,0,0,COUNTA(#REF!)-1,5)
Name CurrencyInput: #REF!
Name d: #REF!
Name dasdfasdfasdf: INDEX(#REF!,COUNTA(#REF!)-#REF!+1):INDEX(#REF!,COUNTA(#REF!))
Name Date: OFFSET(#REF!,COUNTA(#REF!)-1,0,-47,1)

Sheet fund_performance
A1: fund_id | B1: month_end | C1: redemptions | D1: sgg_nav | E1: sgg_nav_source | F1: nav | G1: nav_source | H1: nav_per_share | I1: nav_per_share_source | J1: distributions_per_share | K1: distributions_per_share_source | L1: monthly_return | M1: monthly_return_source | N1: nport_portfolio_count | O1: gav | P1: gav_source | Q1: shares_outstanding | R1: shares_outstanding_source | S1: shares_owned | T1: shares_owned_source | U1: sgg_purchases | V1: sgg_purchases_source | W1: sgg_redemptions | X1: sgg_redemptions_source | Y1: sgg_distributions | Z1: sgg_distributions_source | AA1: gp_count | AB1: gp_count_source | AC1: fund_name | AD1: strategy
A2: 1 | B2: 43982 | H2: 26.04 | I2: pitchbook | AC2: =IFERROR(VLOOKUP($A2,fund_metadata!$A:$P,2,FALSE),"") -> Bow River Evergreen PE | AD2: =IFERROR(VLOOKUP($A2,fund_metadata!$A:$P,16,FALSE),"") -> private_equity
A3: 1 | B3: 44012 | H3: 28.71 | I3: pitchbook | L3: 0.1024 | M3: pitchbook | AC3: =IFERROR(VLOOKUP($A3,fund_metadata!$A:$P,2,FALSE),"") -> Bow River Evergreen PE | AD3: =IFERROR(VLOOKUP($A3,fund_metadata!$A:$P,16,FALSE),"") -> private_equity
A4: 1 | B4: 44043 | H4: 28.78 | I4: pitchbook | L4: 0.0026 | M4: pitchbook | AC4: =IFERROR(VLOOKUP($A4,fund_metadata!$A:$P,2,FALSE),"") -> Bow River Evergreen PE | AD4: =IFERROR(VLOOKUP($A4,fund_metadata!$A:$P,16,FALSE),"") -> private_equity
A5: 1 | B5: 44074 | H5: 28.83 | I5: pitchbook | L5: 0.0016 | M5: pitchbook | AC5: =IFERROR(VLOOKUP($A5,fund_metadata!$A:$P,2,FALSE),"") -> Bow River Evergreen PE | AD5: =IFERROR(VLOOKUP($A5,fund_metadata!$A:$P,16,FALSE),"") -> private_equity
A6: 1 | B6: 44104 | H6: 29.26 | I6: pitchbook | L6: 0.0149 | M6: pitchbook | AC6: =IFERROR(VLOOKUP($A6,fund_metadata!$A:$P,2,FALSE),"") -> Bow River Evergreen PE | AD6: =IFERROR(VLOOKUP($A6,fund_metadata!$A:$P,16,FALSE),"") -> private_equity
A7: 1 | B7: 44135 | H7: 29.26 | I7: pitchbook | L7: 0.0001 | M7: pitchbook | AC7: =IFERROR(VLOOKUP($A7,fund_metadata!$A:$P,2,FALSE),"") -> Bow River Evergreen PE | AD7: =IFERROR(VLOOKUP($A7,fund_metadata!$A:$P,16,FALSE),"") -> private_equity
A8: 1 | B8: 44165 | H8: 29.6 | I8: pitchbook | L8: 0.0118 | M8: pitchbook | AC8: =IFERROR(VLOOKUP($A8,fund_metadata!$A:$P,2,FALSE),"") -> Bow River Evergreen PE | AD8: =IFERROR(VLOOKUP($A8,fund_metadata!$A:$P,16,FALSE),"") -> private_equity
A9: 1 | B9: 44196 | H9: 29.58 | I9: pitchbook | L9: -0.0008 | M9: pitchbook | AC9: =IFERROR(VLOOKUP($A9,fund_metadata!$A:$P,2,FALSE),"") -> Bow River Evergreen PE | AD9: =IFERROR(VLOOKUP($A9,fund_metadata!$A:$P,16,FALSE),"") -> private_equity
A10: 1 | B10: 44227 | H10: 30.39 | I10: pitchbook | L10: 0.0273 | M10: pitchbook | AC10: =IFERROR(VLOOKUP($A10,fund_metadata!$A:$P,2,FALSE),"") -> Bow River Evergreen PE | AD10: =IFERROR(VLOOKUP($A10,fund_metadata!$A:$P,16,FALSE),"") -> private_equity
A11: 1 | B11: 44255 | H11: 31.19 | I11: pitchbook | L11: 0.0264 | M11: pitchbook | AC11: =IFERROR(VLOOKUP($A11,fund_metadata!$A:$P,2,FALSE),"") -> Bow River Evergreen PE | AD11: =IFERROR(VLOOKUP($A11,fund_metadata!$A:$P,16,FALSE),"") -> private_equity
A12: 1 | B12: 44286 | H12: 31.77 | I12: pitchbook | L12: 0.0186 | M12: pitchbook | N12: 32 | Q12: 2869318 | R12: N-CSR | AC12: =IFERROR(VLOOKUP($A12,fund_metadata!$A:$P,2,FALSE),"") -> Bow River Evergreen PE | AD12: =IFERROR(VLOOKUP($A12,fund_metadata!$A:$P,16,FALSE),"") -> private_equity
A13: 1 | B13: 44316 | H13: 31.79 | I13: pitchbook | L13: 0.0007 | M13: pitchbook | AC13: =IFERROR(VLOOKUP($A13,fund_metadata!$A:$P,2,FALSE),"") -> Bow River Evergreen PE | AD13: =IFERROR(VLOOKUP($A13,fund_metadata!$A:$P,16,FALSE),"") -> private_equity
A14: 1 | B14: 44347 | H14: 33.04 | I14: pitchbook | L14: 0.0394 | M14: pitchbook | AC14: =IFERROR(VLOOKUP($A14,fund_metadata!$A:$P,2,FALSE),"") -> Bow River Evergreen PE | AD14: =IFERROR(VLOOKUP($A14,fund_metadata!$A:$P,16,FALSE),"") -> private_equity
A15: 1 | B15: 44377 | F15: 127850000 | G15: pitchbook | H15: 33.84 | I15: pitchbook | L15: 0.0242 | M15: pitchbook | N15: 40 | AC15: =IFERROR(VLOOKUP($A15,fund_metadata!$A:$P,2,FALSE),"") -> Bow River Evergreen PE | AD15: =IFERROR(VLOOKUP($A15,fund_metadata!$A:$P,16,FALSE),"") -> private_equity
A16: 1 | B16: 44408 | F16: 131660000 | G16: pitchbook | H16: 34.52 | I16: pitchbook | L16: 0.02 | M16: pitchbook | AC16: =IFERROR(VLOOKUP($A16,fund_metadata!$A:$P,2,FALSE),"") -> Bow River Evergreen PE | AD16: =IFERROR(VLOOKUP($A16,fund_metadata!$A:$P,16,FALSE),"") -> private_equity
A17: 1 | B17: 44439 | F17: 141200000 | G17: pitchbook | H17: 36.01 | I17: pitchbook | L17: 0.0432 | M17: pitchbook | AC17: =IFERROR(VLOOKUP($A17,fund_metadata!$A:$P,2,FALSE),"") -> Bow River Evergreen PE | AD17: =IFERROR(VLOOKUP($A17,fund_metadata!$A:$P,16,FALSE),"") -> private_equity
A18: 1 | B18: 44469 | F18: 150110000 | G18: pitchbook | H18: 36.75 | I18: pitchbook | L18: 0.0204 | M18: pitchbook | N18: 46 | Q18: 4085205 | R18: N-CSRS | AC18: =IFERROR(VLOOKUP($A18,fund_metadata!$A:$P,2,FALSE),"") -> Bow River Evergreen PE | AD18: =IFERROR(VLOOKUP($A18,fund_metadata!$A:$P,16,FALSE),"") -> private_equity
A19: 1 | B19: 44500 | F19: 152780000 | G19: pitchbook | H19: 36.76 | I19: pitchbook | L19: 0.0004 | M19: pitchbook | AC19: =IFERROR(VLOOKUP($A19,fund_metadata!$A:$P,2,FALSE),"") -> Bow River Evergreen PE | AD19: =IFERROR(VLOOKUP($A19,fund_metadata!$A:$P,16,FALSE),"") -> private_equity
A20: 1 | B20: 44530 | F20: 172670000 | G20: pitchbook | H20: 38.41 | I20: pitchbook | L20: 0.0449 | M20: pitchbook | AC20: =IFERROR(VLOOKUP($A20,fund_metadata!$A:$P,2,FALSE),"") -> Bow River Evergreen PE | AD20: =IFERROR(VLOOKUP($A20,fund_metadata!$A:$P,16,FALSE),"") -> private_equity
A21: 1 | B21: 44561 | F21: 181180000 | G21: pitchbook | H21: 38.38 | I21: pitchbook | L21: 0.0063 | M21: pitchbook | N21: 53 | AC21: =IFERROR(VLOOKUP($A21,fund_metadata!$A:$P,2,FALSE),"") -> Bow River Evergreen PE | AD21: =IFERROR(VLOOKUP($A21,fund_metadata!$A:$P,16,FALSE),"") -> private_equity
A22: 1 | B22: 44592 | F22: 191620000 | G22: pitchbook | H22: 38.01 | I22: pitchbook | L22: -0.0097 | M22: pitchbook | AC22: =IFERROR(VLOOKUP($A22,fund_metadata!$A:$P,2,FALSE),"") -> Bow River Evergreen PE | AD22: =IFERROR(VLOOKUP($A22,fund_metadata!$A:$P,16,FALSE),"") -> private_equity
A23: 1 | B23: 44620 | F23: 206170000 | G23: pitchbook | H23: 38.6 | I23: pitchbook | L23: 0.0157 | M23: pitchbook | AC23: =IFERROR(VLOOKUP($A23,fund_metadata!$A:$P,2,FALSE),"") -> Bow River Evergreen PE | AD23: =IFERROR(VLOOKUP($A23,fund_metadata!$A:$P,16,FALSE),"") -> private_equity
A24: 1 | B24: 44651 | F24: 217280000 | G24: pitchbook | H24: 39.5 | I24: pitchbook | L24: 0.0232 | M24: pitchbook | N24: 64 | O24: 230020000 | P24: pitchbook | Q24: 5341595 | R24: N-CSR | AC24: =IFERROR(VLOOKUP($A24,fund_metadata!$A:$P,2,FALSE),"") -> Bow River Evergreen PE | AD24: =IFERROR(VLOOKUP($A24,fund_metadata!$A:$P,16,FALSE),"") -> private_equity
A25: 1 | B25: 44681 | F25: 227980000 | G25: pitchbook | H25: 39.68 | I25: pitchbook | L25: 0.0045 | M25: pitchbook | AC25: =IFERROR(VLOOKUP($A25,fund_metadata!$A:$P,2,FALSE),"") -> Bow River Evergreen PE | AD25: =IFERROR(VLOOKUP($A25,fund_metadata!$A:$P,16,FALSE),"") -> private_equity
A26: 1 | B26: 44712 | F26: 238290000 | G26: pitchbook | H26: 40.13 | I26: pitchbook | L26: 0.0114 | M26: pitchbook | AC26: =IFERROR(VLOOKUP($A26,fund_metadata!$A:$P,2,FALSE),"") -> Bow River Evergreen PE | AD26: =IFERROR(VLOOKUP($A26,fund_metadata!$A:$P,16,FALSE),"") -> private_equity
A27: 1 | B27: 44742 | F27: 247830000 | G27: pitchbook | H27: 39.92 | I27: pitchbook | L27: -0.0053 | M27: pitchbook | N27: 79 | AC27: =IFERROR(VLOOKUP($A27,fund_metadata!$A:$P,2,FALSE),"") -> Bow River Evergreen PE | AD27: =IFERROR(VLOOKUP($A27,fund_metadata!$A:$P,16,FALSE),"") -> private_equity
A28: 1 | B28: 44773 | F28: 257890000 | G28: pitchbook | H28: 39.76 | I28: pitchbook | L28: -0.0039 | M28: pitchbook | AC28: =IFERROR(VLOOKUP($A28,fund_metadata!$A:$P,2,FALSE),"") -> Bow River Evergreen PE | AD28: =IFERROR(VLOOKUP($A28,fund_metadata!$A:$P,16,FALSE),"") -> private_equity
A29: 1 | B29: 44804 | F29: 269150000 | G29: pitchbook | H29: 39.94 | I29: pitchbook | L29: 0.0045 | M29: pitchbook | AC29: =IFERROR(VLOOKUP($A29,fund_metadata!$A:$P,2,FALSE),"") -> Bow River Evergreen PE | AD29: =IFERROR(VLOOKUP($A29,fund_metadata!$A:$P,16,FALSE),"") -> private_equity
A30: 1 | B30: 44834 | F30: 279610000 | G30: pitchbook | H30: 39.87 | I30: pitchbook | L30: -0.0018 | M30: pitchbook | N30: 88 | O30: 292180000 | P30: pitchbook | Q30: 6459606 | R30: N-CSRS | AC30: =IFERROR(VLOOKUP($A30,fund_metadata!$A:$P,2,FALSE),"") -> Bow River Evergreen PE | AD30: =IFERROR(VLOOKUP($A30,fund_metadata!$A:$P,16,FALSE),"") -> private_equity
A31: 1 | B31: 44865 | F31: 286020000 | G31: pitchbook | H31: 39.75 | I31: pitchbook | L31: -0.003 | M31: pitchbook | AC31: =IFERROR(VLOOKUP($A31,fund_metadata!$A:$P,2,FALSE),"") -> Bow River Evergreen PE | AD31: =IFERROR(VLOOKUP($A31,fund_metadata!$A:$P,16,FALSE),"") -> private_equity
A32: 1 | B32: 44895 | F32: 296020000 | G32: pitchbook | H32: 40.18 | I32: pitchbook | L32: 0.0107 | M32: pitchbook | AC32: =IFERROR(VLOOKUP($A32,fund_metadata!$A:$P,2,FALSE),"") -> Bow River Evergreen PE | AD32: =IFERROR(VLOOKUP($A32,fund_metadata!$A:$P,16,FALSE),"") -> private_equity
A33: 1 | B33: 44926 | F33: 299140000 | G33: pitchbook | H33: 39.39 | I33: pitchbook | L33: 0.0081 | M33: pitchbook | N33: 96 | AC33: =IFERROR(VLOOKUP($A33,fund_metadata!$A:$P,2,FALSE),"") -> Bow River Evergreen PE | AD33: =IFERROR(VLOOKUP($A33,fund_metadata!$A:$P,16,FALSE),"") -> private_equity
A34: 1 | B34: 44957 | F34: 314370000 | G34: pitchbook | H34: 39.39 | I34: pitchbook | L34: 0.0001 | M34: pitchbook | AC34: =IFERROR(VLOOKUP($A34,fund_metadata!$A:$P,2,FALSE),"") -> Bow River Evergreen PE | AD34: =IFERROR(VLOOKUP($A34,fund_metadata!$A:$P,16,FALSE),"") -> private_equity
A35: 1 | B35: 44985 | F35: 325700000 | G35: pitchbook | H35: 39.94 | I35: pitchbook | L35: 0.0141 | M35: pitchbook | AC35: =IFERROR(VLOOKUP($A35,fund_metadata!$A:$P,2,FALSE),"") -> Bow River Evergreen PE | AD35: =IFERROR(VLOOKUP($A35,fund_metadata!$A:$P,16,FALSE),"") -> private_equity
A36: 1 | B36: 45016 | F36: 341380000 | G36: pitchbook | H36: 40.09 | I36: pitchbook | L36: 0.0038 | M36: pitchbook | N36: 98 | O36: 353810000 | P36: pitchbook | AC36: =IFERROR(VLOOKUP($A36,fund_metadata!$A:$P,2,FALSE),"") -> Bow River Evergreen PE | AD36: =IFERROR(VLOOKUP($A36,fund_metadata!$A:$P,16,FALSE),"") -> private_equity
A37: 1 | B37: 45046 | F37: 352740000 | G37: pitchbook | H37: 40.41 | I37: pitchbook | L37: 0.0078 | M37: pitchbook | AC37: =IFERROR(VLOOKUP($A37,fund_metadata!$A:$P,2,FALSE),"") -> Bow River Evergreen PE | AD37: =IFERROR(VLOOKUP($A37,fund_metadata!$A:$P,16,FALSE),"") -> private_equity
A38: 1 | B38: 45077 | F38: 357990000 | G38: pitchbook | H38: 40.41 | I38: pitchbook | L38: 0.0002 | M38: pitchbook | AC38: =IFERROR(VLOOKUP($A38,fund_metadata!$A:$P,2,FALSE),"") -> Bow River Evergreen PE | AD38: =IFERROR(VLOOKUP($A38,fund_metadata!$A:$P,16,FALSE),"") -> private_equity
A39: 1 | B39: 45107 | F39: 369270000 | G39: pitchbook | H39: 40.69 | I39: pitchbook | L39: 0.0068 | M39: pitchbook | N39: 98 | AC39: =IFERROR(VLOOKUP($A39,fund_metadata!$A:$P,2,FALSE),"") -> Bow River Evergreen PE | AD39: =IFERROR(VLOOKUP($A39,fund_metadata!$A:$P,16,FALSE),"") -> private_equity
A40: 1 | B40: 45138 | F40: 380550000 | G40: pitchbook | H40: 41.15 | I40: pitchbook | L40: 0.0113 | M40: pitchbook | AC40: =IFERROR(VLOOKUP($A40,fund_metadata!$A:$P,2,FALSE),"") -> Bow River Evergreen PE | AD40: =IFERROR(VLOOKUP($A40,fund_metadata!$A:$P,16,FALSE),"") -> private_equity
...

Sheet pivot
B3: fund_id | C3: month_end | D3: monthly_return | E3: sgg_nav | F3: nav_per_share
B4: 1 | D4: 0.011815493 | E4: 20401211 | F4: 41.856438
B5: 2 | D5: 0.012669231 | E5: 10154379 | F5: 12.136
B6: 3 | D6: 0.0096465517 | E6: 38468270 | F6: 10.800667
B7: 4 | D7: 0.0131625 | E7: 30569224
B8: 5 | D8: 0.0070173913 | E8: 24655005 | F8: 10.1652
B9: 6 | D9: 0.014418182 | E9: 50253288 | F9: 47.998676
B10: 7 | D10: 0.021395238 | E10: 21528691 | F10: 39.979535
C11: 44895 | D11: 0.0959 | F11: 27.4
C12: 44926 | D12: 0.0488 | F12: 27.4
C13: 44957 | D13: 0.0532 | F13: 28.73
C14: 44985 | D14: -0.048 | F14: 30.26
C15: 45016 | D15: 0.0006 | F15: 30.12
C16: 45046 | D16: 0.0029 | F16: 30.13
C17: 45077 | D17: -0.0003 | F17: 30.22
C18: 45107 | D18: 0.0235 | F18: 30.21
C19: 45138 | D19: 0.0052 | F19: 30.92
C20: 45169 | D20: 0.0489 | F20: 31.08
C21: 45199 | D21: 0.0052 | F21: 32.6
C22: 45230 | D22: 0.025 | F22: 32.77
... C48: 46022 | D48: 0.0783 | F48: 52.27
C49: 46053 | D49: 0.0103 | E49: 5051518.9 | F49: 56.29
C50: 46081 | D50: 0.076 | E50: 5435246 | F50: 56.87
C51: 46112 | D51: 0.0129 | E51: 5505418.4 | F51: 61.19
C52: 46142 | D52: 0.0056 | E52: 5536507.4 | F52: 61.98
C53: 46173 | F53: 62.33
B54: 8 | D54: 0.0098515873 | E54: 39978754 | F54: 18.116614
B55: 9 | D55: 0.014194118 | E55: 40446746
B56: 10 | D56: 0.012490476 | E56: 40588235 | F56: 14.90375
B57: 11 | D57: 0.01225625 | E57: 40201307 | F57: 15.513333
B58: Grand Total | D58: 0.012266845 | E58: 3.5724511e+08 | F58: 24.993098

Sheet fund_metadata
A1: fund_id | B1: fund_name | C1: class_inception_date | D1: ticker | E1: cik | F1: share_class_count | G1: sec_name | H1: fund_type | I1: yfinance_link | J1: share_class | K1: direct_statement_name | L1: icapital_name | M1: ms_name | N1: website_link | O1: sgg_holding | P1: strategy | Q1: management_fee | R1: expense_ratio | S1: incentive_fee | T1: gate
A2: 1 | B2: Bow River Evergreen PE | C2: 44196 | D2: EVERX | E2: 1810256 | F2: 2 | G2: Bow River Capital Evergreen Fund | H2: Interval | I2: https://finance.yahoo.com/quote/EVERX/ | J2: Class I | K2: BOW RIVER CAP EVERGREEN FD CL I | N2: https://www.bowriverevergreen.com/ | O2: y | P2: private_equity | Q2: 0.0175 | R2: 0.0299 | T2: 0.05
A3: 2 | B3: Carlyle Alpinvest | C3: 45294 | D3: XCPIX | E3: 1899610 | F3: 4 | G3: Carlyle AlpInvest Private Markets Fund | H3: Tender | I3: https://finance.yahoo.com/quote/XCPIX/ | J3: Class I | K3: Carlyle Alphinvest Prvte Mrkts I | N3: https://www.carlyle.com/capm | O3: y | P3: private_equity | Q3: 0.0125 | R3: 0.0324 | S3: 0.1 | T3: 0.05
A4: 3 | B4: Cliffwater | C4: 44377 | D4: CELFX | E4: 1842754 | F4: 1 | G4: Cliffwater Enhanced Lending Fund | H4: Interval | I4: https://finance.yahoo.com/quote/CELFX/ | J4: Class I | K4: CLIFFWATER ENHANCED LENDING FUND CL I | N4: https://www.cliffwaterfunds.com/celfx | O4: y | P4: private_credit | Q4: 0.0095 | T4: 0.05
A5: 4 | B5: Coller Secondaries | C5: 45383 | E5: 1969180 | F5: 3 | G5: Coller Secondaries Private Equity Opportunities Fund | H5: Tender | J5: Class I | K5: Coller Secondaries Private Equity Opportunities Fund | N5: https://cspef.com/ | O5: y | P5: secondaries | Q5: 0.0165 | T5: 0.05
A6: 5 | B6: Stepstone PC Income | C6: 45446 | D6: CRDEX | E6: 2006100 | F6: 4 | G6: StepStone Private Credit Income Fund | H6: Interval | I6: https://finance.yahoo.com/quote/CRDEX/history/ | J6: Class I | K6: STEPSTONE PRIVATE CREDIT INCOME FD CL I | N6: https://www.stepstonegroup.com/what-we-do/solutions-services/private-wealth-solutions/crdex/ | O6: y | P6: private_credit | Q6: 0.0115 | T6: 0.05
A7: 6 | B7: Stepstone Private Markets | C7: 44105 | D7: XPMIX | E7: 1789470 | F7: 3 | G7: StepStone Private Markets | H7: Tender | I7: https://finance.yahoo.com/quote/XPMIX/ | J7: Class I | K7: STEPSTONE PRIVATE MARKETS I | N7: https://www.stepstonegroup.com/what-we-do/solutions-services/private-wealth-solutions/sprim/ | O7: y | P7: secondaries | Q7: 0.014 | T7: 0.05
A8: 7 | B8: Stepstone PV/Growth | C8: 44866 | D8: XSPIX | E8: 1918642 | F8: 3 | G8: StepStone Private Venture and Growth Fund | H8: Tender | I8: https://finance.yahoo.com/quote/XSPIX/ | J8: Class I | K8: STEPSTONE PRIVATE VENTURE AND GROWTH FD CL I | N8: https://www.stepstonegroup.com/what-we-do/solutions-services/private-wealth-solutions/spring/ | O8: y | P8: venture | Q8: 0.015 | T8: 0.025
A9: 8 | B9: AMG Pantheon | C9: 42304 | D9: XPEIX | E9: 1609211 | F9: 1 | G9: AMG Pantheon Fund, LLC | H9: Tender | J9: Class 3 | L9: AMG PANTHEON FUND CLASS 3 | M9: AMG PANTHEON FUND, LLC ESC | N9: https://www.pantheon.com/private-wealth-overview/amg-pantheon-fund/ | O9: y | P9: secondaries | Q9: 0.0125 | T9: 0.05
A10: 9 | B10: FLEX | C10: 45646 | E10: 2008602 | F10: 4 | G10: Franklin Lexington Private Markets Fund | H10: Tender | J10: Class I | M10: FLEX - CLASS I ESC | N10: https://www.flexpe.com | O10: y | P10: secondaries | Q10: 0.0125 | T10: 0.05
A11: 10 | B11: Hamilton Lane | C11: 44200 | D11: XHLIX | E11: 1803491 | F11: 3 | G11: Hamilton Lane Private Assets Fund | H11: Tender | I11: https://finance.yahoo.com/quote/XHLIX/ | J11: Class I | L11: HAMILTON LANE PVT ASSET FUND CL I | M11: HAMILTON LANE PAF (I) ESC | N11: https://www.hamiltonlane.com/en-us/strategies/evergreen/us-private-wealth/private-assets-fund | O11: y | P11: private_equity | Q11: 0.014 | R11: 0.0338 | S11: 0.1 | T11: 0.05
A12: 11 | B12: JPMF | C12: 45119 | E12: 1940499 | F12: 3 | G12: JPMorgan Private Markets Fund | H12: Tender | J12: Class I | L12: JPMORGAN PRIVATE MARKETS FUND - I | M12: JPMF CLASS I ESC | N12: https://am.jpmorgan.com/us/en/asset-management/adv/products/jpmorgan-private-markets-fund-i-48130f306 | O12: y | P12: private_equity | Q12: 0.01 | T12: 0.05

Sheet pitchbook_tri_index
A1: month_end | B1: pitchbook_index
A2: 41820 | B2: 100
A3: 41851 | B3: 99.922618
A4: 41882 | B4: 100.48179
A5: 41912 | B5: 100.70548
A6: 41943 | B6: 101.05813
A7: 41973 | B7: 101.53131
A8: 42004 | B8: 100.99359
A9: 42035 | B9: 101.15965
A10: 42063 | B10: 102.68618
A11: 42094 | B11: 103.68794
A12: 42124 | B12: 104.06627
A13: 42155 | B13: 104.49655
... A139: 45991 | B139: 219.95068
