Workbook
Name _DLX1.USE: #REF!
Name _Regression_Int: 1
Name a: #REF!
Name aa: #REF!
Name aaa: INDEX(#REF!,COUNTA(#REF!)-#REF!+1):INDEX(#REF!,COUNTA(#REF!))
Name ac: #REF!
Name asdfasdfasdfasdfasdfasdf: INDEX(#REF!,COUNTA(#REF!)-#REF!+1):INDEX(#REF!,COUNTA(#REF!))
Name b: #REF!
Name BHYDailyYield: OFFSET(#REF!,COUNTA(#REF!)-1,0,-254,1)
Name BLoansDailyYield: OFFSET(#REF!,COUNTA(#REF!)-1,0,-254,1)
Name Bond_Swap_Date: OFFSET(#REF!,COUNTA(#REF!)-1,0,-96,1)
Name Bond_Swap_Worst: OFFSET(#REF!,COUNTA(#REF!)-1,0,-96,1)
Name BR: #REF!
Name Business_Stat_Hist: OFFSET(#REF!,0,0,COUNTA(#REF!),5)
Name Ccy: #REF!
Name Chart_2: #REF!
Name CHART_9a: #REF!
Name CHART1: #REF!
Name CHART10: #REF!
Name Chart100: #REF!
Name chart11: #REF!
Name CHART12: #REF!
Name CHART13: #REF!
Name CHART14: #REF!
Name CHART15: #REF!
Name CHART16: #REF!
Name CHART2: #REF!
Name Chart2x: INDEX(#REF!,COUNTA(#REF!)-#REF!+1):INDEX(#REF!,COUNTA(#REF!))
Name CHART3: #REF!
Name Chart3x: #N/A
Name CHART4: #REF!
Name CHART5: #REF!
Name CHART6: #REF!
Name CHART7: #REF!
Name CHART8: #REF!
Name CHART9: #REF!
Name CHART9a: #REF!
Name clean_spreads: #REF!
Name CLPercent: INDEX(#REF!,COUNTA(#REF!)-#REF!+1):INDEX(#REF!,COUNTA(#REF!))
Name CLpercentYR: INDEX(#REF!,COUNTA(#REF!)-#REF!+1):INDEX(#REF!,COUNTA(#REF!))
Name CLQTR: #REF!
Name CLVolMN: #REF!
Name CLVolume: INDEX(#REF!,COUNTA(#REF!)-#REF!+1):INDEX(#REF!,COUNTA(#REF!))
Name CLVolumeYR: INDEX(#REF!,COUNTA(#REF!)-#REF!+1):INDEX(#REF!,COUNTA(#REF!))
Name CommercialExAIGMetrics: #REF!
Name Copyright: #REF!
Name CopyrightAnalytics: #REF!
Name CreatedFor: #REF!
Name CreatedForTitle: #REF!
Name CS_ALL: OFFSET(#REF!, COUNTA(#REF!)-1,0,-13,1)
Name CS_LBO: OFFSET(#REF!, COUNTA(#REF!)-1,0,-13,1)
Name CS_MA: OFFSET(#REF!, COUNTA(#REF!)-1,0,-13,1)
Name CS_Period: OFFSET(#REF!, COUNTA(#REF!)-1,0,-13,1)
Name Currency_Table: OFFSET(#REF!,0,0,COUNTA(#REF!)-1,5)
Name Currency_Table2: OFFSET(#REF!,0,0,COUNTA(#REF!)-1,5)
Name Currency_Table3: OFFSET(#REF!,0,0,COUNTA(#REF!)-1,5)
Name CurrencyInput: #REF!
Name d: #REF!
Name dasdfasdfasdf: INDEX(#REF!,COUNTA(#REF!)-#REF!+1):INDEX(#REF!,COUNTA(#REF!))
Name Date: OFFSET(#REF!,COUNTA(#REF!)-1,0,-47,1)

Sheet fund_performance
A1: fund_id | B1: month_end | C1: sgg_nav | D1: sgg_nav_source | E1: nav | F1: nav_source | G1: nav_per_share | H1: nav_per_share_source | I1: distributions_per_share | J1: distributions_per_share_source | K1: monthly_return | L1: monthly_return_source | M1: nport_portfolio_count | N1: gav | O1: gav_source | P1: shares_outstanding | Q1: shares_outstanding_source | R1: shares_owned | S1: shares_owned_source | T1: sgg_purchases | U1: sgg_purchases_source | V1: sgg_redemptions | W1: sgg_redemptions_source | X1: sgg_distributions | Y1: sgg_distributions_source | Z1: gp_count | AA1: gp_count_source | AB1: fund_name | AC1: strategy
A2: 1 | B2: 46173 | G2: 55.56 | H2: pitchbook | AB2: =IFERROR(VLOOKUP($A2,fund_metadata!$A:$P,2,FALSE),"") -> Bow River Evergreen PE | AC2: =IFERROR(VLOOKUP($A2,fund_metadata!$A:$P,16,FALSE),"") -> private_equity
A3: 1 | B3: 46142 | C3: 5132009.8 | D3: black diamond | E3: 1240000000 | F3: pitchbook | G3: 55.17 | H3: pitchbook | K3: 0.0034 | L3: pitchbook | AB3: =IFERROR(VLOOKUP($A3,fund_metadata!$A:$P,2,FALSE),"") -> Bow River Evergreen PE | AC3: =IFERROR(VLOOKUP($A3,fund_metadata!$A:$P,16,FALSE),"") -> private_equity
A4: 1 | B4: 46112 | C4: 5114594.6 | D4: direct fund statement | E4: 1220000000 | F4: pitchbook | G4: 54.98 | H4: pitchbook | K4: 0.0039 | L4: pitchbook | M4: 198 | R4: 93030.179 | S4: direct fund statement | T4: 0 | U4: direct fund statement | V4: 0 | W4: direct fund statement | X4: 0 | Y4: direct fund statement | AB4: =IFERROR(VLOOKUP($A4,fund_metadata!$A:$P,2,FALSE),"") -> Bow River Evergreen PE | AC4: =IFERROR(VLOOKUP($A4,fund_metadata!$A:$P,16,FALSE),"") -> private_equity
A5: 1 | B5: 46081 | C5: 5094704.7 | D5: direct fund statement | E5: 1190000000 | F5: pitchbook | G5: 54.76 | H5: pitchbook | K5: 0.0069 | L5: pitchbook | R5: 93030.179 | S5: direct fund statement | T5: 0 | U5: direct fund statement | V5: 0 | W5: direct fund statement | X5: 0 | Y5: direct fund statement | AB5: =IFERROR(VLOOKUP($A5,fund_metadata!$A:$P,2,FALSE),"") -> Bow River Evergreen PE | AC5: =IFERROR(VLOOKUP($A5,fund_metadata!$A:$P,16,FALSE),"") -> private_equity
A6: 1 | B6: 46053 | C6: 5059902.1 | D6: direct fund statement | E6: 1160000000 | F6: pitchbook | G6: 54.39 | H6: pitchbook | K6: 0.012 | L6: pitchbook | R6: 93030.179 | S6: direct fund statement | T6: 5000000 | U6: direct fund statement | V6: 0 | W6: direct fund statement | X6: 0 | Y6: direct fund statement | AB6: =IFERROR(VLOOKUP($A6,fund_metadata!$A:$P,2,FALSE),"") -> Bow River Evergreen PE | AC6: =IFERROR(VLOOKUP($A6,fund_metadata!$A:$P,16,FALSE),"") -> private_equity
A7: 1 | B7: 46022 | E7: 1120000000 | F7: pitchbook | G7: 53.75 | H7: pitchbook | K7: -0.0113 | L7: pitchbook | M7: 185 | AB7: =IFERROR(VLOOKUP($A7,fund_metadata!$A:$P,2,FALSE),"") -> Bow River Evergreen PE | AC7: =IFERROR(VLOOKUP($A7,fund_metadata!$A:$P,16,FALSE),"") -> private_equity
A8: 1 | B8: 45991 | E8: 1090000000 | F8: pitchbook | G8: 54.36 | H8: pitchbook | K8: 0.0319 | L8: pitchbook | AB8: =IFERROR(VLOOKUP($A8,fund_metadata!$A:$P,2,FALSE),"") -> Bow River Evergreen PE | AC8: =IFERROR(VLOOKUP($A8,fund_metadata!$A:$P,16,FALSE),"") -> private_equity
A9: 1 | B9: 45961 | E9: 1050000000 | F9: pitchbook | G9: 52.68 | H9: pitchbook | K9: 0.0125 | L9: pitchbook | AB9: =IFERROR(VLOOKUP($A9,fund_metadata!$A:$P,2,FALSE),"") -> Bow River Evergreen PE | AC9: =IFERROR(VLOOKUP($A9,fund_metadata!$A:$P,16,FALSE),"") -> private_equity
A10: 1 | B10: 45930 | E10: 1000000000 | F10: pitchbook | G10: 52.03 | H10: pitchbook | K10: 0.0066 | L10: pitchbook | M10: 176 | N10: 1040000000 | O10: pitchbook | P10: 18405421 | Q10: N-CSRS | AB10: =IFERROR(VLOOKUP($A10,fund_metadata!$A:$P,2,FALSE),"") -> Bow River Evergreen PE | AC10: =IFERROR(VLOOKUP($A10,fund_metadata!$A:$P,16,FALSE),"") -> private_equity
A11: 1 | B11: 45900 | E11: 942530000 | F11: pitchbook | G11: 51.69 | H11: pitchbook | K11: 0.0191 | L11: pitchbook | AB11: =IFERROR(VLOOKUP($A11,fund_metadata!$A:$P,2,FALSE),"") -> Bow River Evergreen PE | AC11: =IFERROR(VLOOKUP($A11,fund_metadata!$A:$P,16,FALSE),"") -> private_equity
A12: 1 | B12: 45869 | E12: 894140000 | F12: pitchbook | G12: 50.72 | H12: pitchbook | K12: -0.002 | L12: pitchbook | AB12: =IFERROR(VLOOKUP($A12,fund_metadata!$A:$P,2,FALSE),"") -> Bow River Evergreen PE | AC12: =IFERROR(VLOOKUP($A12,fund_metadata!$A:$P,16,FALSE),"") -> private_equity
A13: 1 | B13: 45838 | E13: 849670000 | F13: pitchbook | G13: 50.82 | H13: pitchbook | I13: 0 | J13: yfinance | K13: 0.0004 | L13: pitchbook | M13: 157 | AB13: =IFERROR(VLOOKUP($A13,fund_metadata!$A:$P,2,FALSE),"") -> Bow River Evergreen PE | AC13: =IFERROR(VLOOKUP($A13,fund_metadata!$A:$P,16,FALSE),"") -> private_equity
A14: 1 | B14: 45808 | E14: 826540000 | F14: pitchbook | G14: 50.8 | H14: pitchbook | I14: 0 | J14: yfinance | K14: 0.0142 | L14: pitchbook | AB14: =IFERROR(VLOOKUP($A14,fund_metadata!$A:$P,2,FALSE),"") -> Bow River Evergreen PE | AC14: =IFERROR(VLOOKUP($A14,fund_metadata!$A:$P,16,FALSE),"") -> private_equity
A15: 1 | B15: 45777 | E15: 807000000 | F15: pitchbook | G15: 50.09 | H15: pitchbook | I15: 0 | J15: yfinance | K15: 0.0081 | L15: pitchbook | AB15: =IFERROR(VLOOKUP($A15,fund_metadata!$A:$P,2,FALSE),"") -> Bow River Evergreen PE | AC15: =IFERROR(VLOOKUP($A15,fund_metadata!$A:$P,16,FALSE),"") -> private_equity
A16: 1 | B16: 45747 | E16: 774220000 | F16: pitchbook | G16: 49.69 | H16: pitchbook | I16: 0 | J16: yfinance | K16: 0.0182 | L16: pitchbook | M16: 147 | N16: 817800000 | O16: pitchbook | P16: 14550293 | Q16: N-CSR | AB16: =IFERROR(VLOOKUP($A16,fund_metadata!$A:$P,2,FALSE),"") -> Bow River Evergreen PE | AC16: =IFERROR(VLOOKUP($A16,fund_metadata!$A:$P,16,FALSE),"") -> private_equity
A17: 1 | B17: 45716 | E17: 735550000 | F17: pitchbook | G17: 48.8 | H17: pitchbook | I17: 0 | J17: yfinance | K17: 0.0215 | L17: pitchbook | AB17: =IFERROR(VLOOKUP($A17,fund_metadata!$A:$P,2,FALSE),"") -> Bow River Evergreen PE | AC17: =IFERROR(VLOOKUP($A17,fund_metadata!$A:$P,16,FALSE),"") -> private_equity
A18: 1 | B18: 45688 | E18: 701580000 | F18: pitchbook | G18: 47.77 | H18: pitchbook | I18: 0 | J18: yfinance | K18: 0.005 | L18: pitchbook | AB18: =IFERROR(VLOOKUP($A18,fund_metadata!$A:$P,2,FALSE),"") -> Bow River Evergreen PE | AC18: =IFERROR(VLOOKUP($A18,fund_metadata!$A:$P,16,FALSE),"") -> private_equity
A19: 1 | B19: 45657 | E19: 669420000 | F19: pitchbook | G19: 47.54 | H19: pitchbook | I19: 1.137 | J19: yfinance | K19: 0.004 | L19: pitchbook | M19: 142 | AB19: =IFERROR(VLOOKUP($A19,fund_metadata!$A:$P,2,FALSE),"") -> Bow River Evergreen PE | AC19: =IFERROR(VLOOKUP($A19,fund_metadata!$A:$P,16,FALSE),"") -> private_equity
A20: 1 | B20: 45626 | E20: 658210000 | F20: pitchbook | G20: 48.48 | H20: pitchbook | I20: 0 | J20: yfinance | K20: 0.0115 | L20: pitchbook | AB20: =IFERROR(VLOOKUP($A20,fund_metadata!$A:$P,2,FALSE),"") -> Bow River Evergreen PE | AC20: =IFERROR(VLOOKUP($A20,fund_metadata!$A:$P,16,FALSE),"") -> private_equity
A21: 1 | B21: 45596 | E21: 633880000 | F21: pitchbook | G21: 47.94 | H21: pitchbook | I21: 0 | J21: yfinance | K21: 0.0028 | L21: pitchbook | AB21: =IFERROR(VLOOKUP($A21,fund_metadata!$A:$P,2,FALSE),"") -> Bow River Evergreen PE | AC21: =IFERROR(VLOOKUP($A21,fund_metadata!$A:$P,16,FALSE),"") -> private_equity
A22: 1 | B22: 45565 | E22: 617640000 | F22: pitchbook | G22: 47.8 | H22: pitchbook | I22: 0 | J22: yfinance | K22: 0.0119 | L22: pitchbook | M22: 131 | N22: 632440000 | O22: pitchbook | P22: 12219603 | Q22: N-CSRS | AB22: =IFERROR(VLOOKUP($A22,fund_metadata!$A:$P,2,FALSE),"") -> Bow River Evergreen PE | AC22: =IFERROR(VLOOKUP($A22,fund_metadata!$A:$P,16,FALSE),"") -> private_equity
A23: 1 | B23: 45535 | E23: 600190000 | F23: pitchbook | G23: 47.24 | H23: pitchbook | I23: 0 | J23: yfinance | K23: 0.029 | L23: pitchbook | AB23: =IFERROR(VLOOKUP($A23,fund_metadata!$A:$P,2,FALSE),"") -> Bow River Evergreen PE | AC23: =IFERROR(VLOOKUP($A23,fund_metadata!$A:$P,16,FALSE),"") -> private_equity
A24: 1 | B24: 45504 | E24: 565090000 | F24: pitchbook | G24: 45.9 | H24: pitchbook | I24: 0 | J24: yfinance | K24: 0.0011 | L24: pitchbook | AB24: =IFERROR(VLOOKUP($A24,fund_metadata!$A:$P,2,FALSE),"") -> Bow River Evergreen PE | AC24: =IFERROR(VLOOKUP($A24,fund_metadata!$A:$P,16,FALSE),"") -> private_equity
A25: 1 | B25: 45473 | E25: 552750000 | F25: pitchbook | G25: 45.85 | H25: pitchbook | I25: 0 | J25: yfinance | K25: 0.0004 | L25: pitchbook | M25: 121 | AB25: =IFERROR(VLOOKUP($A25,fund_metadata!$A:$P,2,FALSE),"") -> Bow River Evergreen PE | AC25: =IFERROR(VLOOKUP($A25,fund_metadata!$A:$P,16,FALSE),"") -> private_equity
A26: 1 | B26: 45443 | E26: 530130000 | F26: pitchbook | G26: 45.83 | H26: pitchbook | K26: 0.0212 | L26: pitchbook | AB26: =IFERROR(VLOOKUP($A26,fund_metadata!$A:$P,2,FALSE),"") -> Bow River Evergreen PE | AC26: =IFERROR(VLOOKUP($A26,fund_metadata!$A:$P,16,FALSE),"") -> private_equity
A27: 1 | B27: 45412 | E27: 509290000 | F27: pitchbook | G27: 44.88 | H27: pitchbook | K27: 0.0134 | L27: pitchbook | AB27: =IFERROR(VLOOKUP($A27,fund_metadata!$A:$P,2,FALSE),"") -> Bow River Evergreen PE | AC27: =IFERROR(VLOOKUP($A27,fund_metadata!$A:$P,16,FALSE),"") -> private_equity
A28: 1 | B28: 45382 | E28: 486790000 | F28: pitchbook | G28: 44.29 | H28: pitchbook | K28: 0.0082 | L28: pitchbook | M28: 112 | N28: 519920000 | O28: pitchbook | P28: 10327322 | Q28: N-CSR | AB28: =IFERROR(VLOOKUP($A28,fund_metadata!$A:$P,2,FALSE),"") -> Bow River Evergreen PE | AC28: =IFERROR(VLOOKUP($A28,fund_metadata!$A:$P,16,FALSE),"") -> private_equity
A29: 1 | B29: 45351 | E29: 476530000 | F29: pitchbook | G29: 43.93 | H29: pitchbook | K29: 0.0131 | L29: pitchbook | AB29: =IFERROR(VLOOKUP($A29,fund_metadata!$A:$P,2,FALSE),"") -> Bow River Evergreen PE | AC29: =IFERROR(VLOOKUP($A29,fund_metadata!$A:$P,16,FALSE),"") -> private_equity
A30: 1 | B30: 45322 | E30: 459740000 | F30: pitchbook | G30: 43.36 | H30: pitchbook | K30: -0.0002 | L30: pitchbook | AB30: =IFERROR(VLOOKUP($A30,fund_metadata!$A:$P,2,FALSE),"") -> Bow River Evergreen PE | AC30: =IFERROR(VLOOKUP($A30,fund_metadata!$A:$P,16,FALSE),"") -> private_equity
A31: 1 | B31: 45291 | E31: 446350000 | F31: pitchbook | G31: 43.37 | H31: pitchbook | K31: 0.0018 | L31: pitchbook | M31: 106 | AB31: =IFERROR(VLOOKUP($A31,fund_metadata!$A:$P,2,FALSE),"") -> Bow River Evergreen PE | AC31: =IFERROR(VLOOKUP($A31,fund_metadata!$A:$P,16,FALSE),"") -> private_equity
A32: 1 | B32: 45260 | E32: 438230000 | F32: pitchbook | G32: 43.98 | H32: pitchbook | K32: 0.012 | L32: pitchbook | AB32: =IFERROR(VLOOKUP($A32,fund_metadata!$A:$P,2,FALSE),"") -> Bow River Evergreen PE | AC32: =IFERROR(VLOOKUP($A32,fund_metadata!$A:$P,16,FALSE),"") -> private_equity
A33: 1 | B33: 45230 | E33: 427670000 | F33: pitchbook | G33: 43.45 | H33: pitchbook | K33: 0.0371 | L33: pitchbook | AB33: =IFERROR(VLOOKUP($A33,fund_metadata!$A:$P,2,FALSE),"") -> Bow River Evergreen PE | AC33: =IFERROR(VLOOKUP($A33,fund_metadata!$A:$P,16,FALSE),"") -> private_equity
A34: 1 | B34: 45199 | E34: 400100000 | F34: pitchbook | G34: 41.9 | H34: pitchbook | K34: -0.0023 | L34: pitchbook | M34: 105 | N34: 412100000 | O34: pitchbook | P34: 8965808 | Q34: N-CSRS | AB34: =IFERROR(VLOOKUP($A34,fund_metadata!$A:$P,2,FALSE),"") -> Bow River Evergreen PE | AC34: =IFERROR(VLOOKUP($A34,fund_metadata!$A:$P,16,FALSE),"") -> private_equity
A35: 1 | B35: 45169 | E35: 395660000 | F35: pitchbook | G35: 42 | H35: pitchbook | K35: 0.0206 | L35: pitchbook | AB35: =IFERROR(VLOOKUP($A35,fund_metadata!$A:$P,2,FALSE),"") -> Bow River Evergreen PE | AC35: =IFERROR(VLOOKUP($A35,fund_metadata!$A:$P,16,FALSE),"") -> private_equity
A36: 1 | B36: 45138 | E36: 380550000 | F36: pitchbook | G36: 41.15 | H36: pitchbook | K36: 0.0113 | L36: pitchbook | AB36: =IFERROR(VLOOKUP($A36,fund_metadata!$A:$P,2,FALSE),"") -> Bow River Evergreen PE | AC36: =IFERROR(VLOOKUP($A36,fund_metadata!$A:$P,16,FALSE),"") -> private_equity
A37: 1 | B37: 45107 | E37: 369270000 | F37: pitchbook | G37: 40.69 | H37: pitchbook | K37: 0.0068 | L37: pitchbook | M37: 98 | AB37: =IFERROR(VLOOKUP($A37,fund_metadata!$A:$P,2,FALSE),"") -> Bow River Evergreen PE | AC37: =IFERROR(VLOOKUP($A37,fund_metadata!$A:$P,16,FALSE),"") -> private_equity
A38: 1 | B38: 45077 | E38: 357990000 | F38: pitchbook | G38: 40.41 | H38: pitchbook | K38: 0.0002 | L38: pitchbook | AB38: =IFERROR(VLOOKUP($A38,fund_metadata!$A:$P,2,FALSE),"") -> Bow River Evergreen PE | AC38: =IFERROR(VLOOKUP($A38,fund_metadata!$A:$P,16,FALSE),"") -> private_equity
A39: 1 | B39: 45046 | E39: 352740000 | F39: pitchbook | G39: 40.41 | H39: pitchbook | K39: 0.0078 | L39: pitchbook | AB39: =IFERROR(VLOOKUP($A39,fund_metadata!$A:$P,2,FALSE),"") -> Bow River Evergreen PE | AC39: =IFERROR(VLOOKUP($A39,fund_metadata!$A:$P,16,FALSE),"") -> private_equity
A40: 1 | B40: 45016 | E40: 341380000 | F40: pitchbook | G40: 40.09 | H40: pitchbook | K40: 0.0038 | L40: pitchbook | M40: 98 | N40: 353810000 | O40: pitchbook | AB40: =IFERROR(VLOOKUP($A40,fund_metadata!$A:$P,2,FALSE),"") -> Bow River Evergreen PE | AC40: =IFERROR(VLOOKUP($A40,fund_metadata!$A:$P,16,FALSE),"") -> private_equity
...

Sheet fund_metadata
A1: fund_id | B1: fund_name | C1: ticker | D1: cik | E1: share_class_count | F1: sec_name | G1: fund_type | H1: yfinance_link | I1: share_class | J1: direct_statement_name | K1: icapital_name | L1: ms_name | M1: website_link | N1: sgg_holding | O1: class_inception_date | P1: strategy | Q1: management_fee | R1: expense_ratio | S1: incentve_fee | T1: repurchases_liquidity
A2: 1 | B2: Bow River Evergreen PE | C2: EVERX | D2: 1810256 | E2: 2 | F2: Bow River Capital Evergreen Fund | G2: Interval | H2: https://finance.yahoo.com/quote/EVERX/ | I2: Class I | J2: BOW RIVER CAP EVERGREEN FD CL I | M2: https://www.bowriverevergreen.com/ | N2: y | O2: 44196 | P2: private_equity | Q2: 0.0175 | R2: 0.0299
A3: 2 | B3: Carlyle Alpinvest | C3: XCPIX | D3: 1899610 | E3: 4 | F3: Carlyle AlpInvest Private Markets Fund | G3: Tender | H3: https://finance.yahoo.com/quote/XCPIX/ | I3: Class I | J3: Carlyle Alphinvest Prvte Mrkts I | M3: https://www.carlyle.com/capm | N3: y | O3: 45294 | P3: private_equity | Q3: 0.0125 | R3: 0.0324 | S3: 0.1
A4: 3 | B4: Cliffwater | C4: CELFX | D4: 1842754 | E4: 1 | F4: Cliffwater Enhanced Lending Fund | G4: Interval | H4: https://finance.yahoo.com/quote/CELFX/ | I4: Class I | J4: CLIFFWATER ENHANCED LENDING FUND CL I | M4: https://www.cliffwaterfunds.com/celfx | N4: y | O4: 44377 | P4: private_credit | Q4: 0.0095
A5: 4 | B5: Coller Secondaries | D5: 1969180 | E5: 3 | F5: Coller Secondaries Private Equity Opportunities Fund | G5: Tender | I5: Class I | J5: Coller Secondaries Private Equity Opportunities Fund | M5: https://cspef.com/ | N5: y | O5: 45383 | P5: secondaries | Q5: 0.0165
A6: 5 | B6: Stepstone PC Income | C6: CRDEX | D6: 2006100 | E6: 4 | F6: StepStone Private Credit Income Fund | G6: Interval | H6: https://finance.yahoo.com/quote/CRDEX/history/ | I6: Class I | J6: STEPSTONE PRIVATE CREDIT INCOME FD CL I | M6: https://www.stepstonegroup.com/what-we-do/solutions-services/private-wealth-solutions/crdex/ | N6: y | O6: 45446 | P6: private_credit | Q6: 0.0115
A7: 6 | B7: Stepstone Private Markets | C7: XPMIX | D7: 1789470 | E7: 3 | F7: StepStone Private Markets | G7: Tender | H7: https://finance.yahoo.com/quote/XPMIX/ | I7: Class I | J7: STEPSTONE PRIVATE MARKETS I | M7: https://www.stepstonegroup.com/what-we-do/solutions-services/private-wealth-solutions/sprim/ | N7: y | O7: 44105 | P7: secondaries | Q7: 0.014
A8: 7 | B8: Stepstone PV/Growth | C8: XSPIX | D8: 1918642 | E8: 3 | F8: StepStone Private Venture and Growth Fund | G8: Tender | H8: https://finance.yahoo.com/quote/XSPIX/ | I8: Class I | J8: STEPSTONE PRIVATE VENTURE AND GROWTH FD CL I | M8: https://www.stepstonegroup.com/what-we-do/solutions-services/private-wealth-solutions/spring/ | N8: y | O8: 44866 | P8: venture | Q8: 0.015 | T8: 0.025
A9: 8 | B9: AMG Pantheon | C9: XPEIX | D9: 1609211 | E9: 1 | F9: AMG Pantheon Fund, LLC | G9: Tender | I9: Class 3 | K9: AMG PANTHEON FUND CLASS 3 | L9: AMG PANTHEON FUND, LLC ESC | M9: https://www.pantheon.com/private-wealth-overview/amg-pantheon-fund/ | N9: y | O9: 42304 | P9: secondaries | Q9: 0.0125
A10: 9 | B10: FLEX | D10: 2008602 | E10: 4 | F10: Franklin Lexington Private Markets Fund | G10: Tender | I10: Class I | L10: FLEX - CLASS I ESC | M10: https://www.flexpe.com | N10: y | O10: 45646 | P10: secondaries | Q10: 0.0125
A11: 10 | B11: Hamilton Lane | C11: XHLIX | D11: 1803491 | E11: 3 | F11: Hamilton Lane Private Assets Fund | G11: Tender | H11: https://finance.yahoo.com/quote/XHLIX/ | I11: Class I | K11: HAMILTON LANE PVT ASSET FUND CL I | L11: HAMILTON LANE PAF (I) ESC | M11: https://www.hamiltonlane.com/en-us/strategies/evergreen/us-private-wealth/private-assets-fund | N11: y | O11: 44200 | P11: private_equity | Q11: 0.014 | R11: 0.0338 | S11: 0.1 | T11: 0.05
A12: 11 | B12: JPMF | D12: 1940499 | E12: 3 | F12: JPMorgan Private Markets Fund | G12: Tender | I12: Class I | K12: JPMORGAN PRIVATE MARKETS FUND - I | L12: JPMF CLASS I ESC | M12: https://am.jpmorgan.com/us/en/asset-management/adv/products/jpmorgan-private-markets-fund-i-48130f306 | N12: y | O12: 45119 | P12: private_equity | Q12: 0.01

Sheet pitchbook_tri_index
A1: month_end | B1: pitchbook_index
A2: 41820 | B2: 100
A3: 41851 | B3: 99.922618
A4: 41882 | B4: 100.48179
A5: 41912 | B5: 100.70548
A6: 41943 | B6: 101.05813
A7: 41973 | B7: 101.53131
A8: 42004 | B8: 100.99359
A9: 42035 | B9: 101.15965
A10: 42063 | B10: 102.68618
A11: 42094 | B11: 103.68794
A12: 42124 | B12: 104.06627
A13: 42155 | B13: 104.49655
... A139: 45991 | B139: 219.95068
