Workbook
Name _1900_Minority_Interest: [5]summary!#REF!
Name _1995_Asset_Sales: [5]summary!#REF!
Name _1995_Capex: [5]summary!#REF!
Name _1995_Capitalized_Interest: [5]summary!#REF!
Name _1995_Cash_Flow: [5]summary!#REF!
Name _1995_Current_Income_Tax: [5]summary!#REF!
Name _1995_DD_A: [5]summary!#REF!
Name _1995_Deferred_Income_Tax: [5]summary!#REF!
Name _1995_EBIT: [5]summary!#REF!
Name _1995_EBITDAX: [5]summary!#REF!
Name _1995_Exploration_Expense: [5]summary!#REF!
Name _1995_Interest_Expense: [5]summary!#REF!
Name _1995_Net_Income: [5]summary!#REF!
Name _1995_Other_Income: [5]summary!#REF!
Name _1995_Other_Non_Cash_Items: [5]summary!#REF!
Name _1995_Revenue: [5]summary!#REF!
Name _1995_Weighted_Average_Shares_Outstanding: [5]summary!#REF!
Name _1997E_Asset_Sales: [5]summary!#REF!
Name _1997E_Capex: [5]summary!#REF!
Name _1997E_Capitalized_Interest: [5]summary!#REF!
Name _1997E_Cash_Flow: [5]summary!#REF!
Name _1997E_Current_Income_Tax: [5]summary!#REF!
Name _1997E_DD_A: [5]summary!#REF!
Name _1997E_Deferred_Income_Tax: [5]summary!#REF!
Name _1997E_EBIT: [5]summary!#REF!
Name _1997E_EBITDAX: [5]summary!#REF!
Name _1997E_Exploration_Expense: [5]summary!#REF!
Name _1997E_Interest_Expense: [5]summary!#REF!
Name _1997E_Minority_Interest: [5]summary!#REF!
Name _1997E_Net_Income: [5]summary!#REF!
Name _1997E_Other_Income: [5]summary!#REF!
Name _1997E_Other_Non_Cash_Items: [5]summary!#REF!
Name _1997E_Revenue: [5]summary!#REF!
Name _1997E_Weighted_Average_Shares_Outstanding: [5]summary!#REF!
Name _1998E_Asset_Sales: [5]summary!#REF!
Name _1998E_Capex: [5]summary!#REF!
Name _1998E_Capitalized_Interest: [5]summary!#REF!
Name _1998E_Cash_Flow: [5]summary!#REF!
Name _1998E_Current_Income_Tax: [5]summary!#REF!
Name _1998E_DD_A: [5]summary!#REF!
Name _1998E_Deferred_Income_Tax: [5]summary!#REF!
Name _1998E_EBIT: [5]summary!#REF!
Name _1998E_EBITDAX: [5]summary!#REF!
Name _1998E_Exploration_Expense: [5]summary!#REF!
Name _1998E_Interest_Expense: [5]summary!#REF!
Name _1998E_Minority_Interest: [5]summary!#REF!
Name _1998E_Net_Income: [5]summary!#REF!
Name _1998E_Other_Income: [5]summary!#REF!
Name _1998E_Other_Non_Cash_Items: [5]summary!#REF!
Name _1998E_Revenue: [5]summary!#REF!
Name _1998E_Weighted_Average_Shares_Outstanding: [5]summary!#REF!
Name _1999E_Asset_Sales: [5]summary!#REF!
Name _1999E_Capex: [5]summary!#REF!
Name _1999E_Capitalized_Interest: [5]summary!#REF!
Name _1999E_Cash_Flow: [5]summary!#REF!
Name _1999E_Current_Income_Tax: [5]summary!#REF!
Name _1999E_DD_A: [5]summary!#REF!
Name _1999E_Deferred_Income_Tax: [5]summary!#REF!
Name _1999E_EBIT: [5]summary!#REF!
Name _1999E_EBITDAX: [5]summary!#REF!

Sheet fund_performance
A1: fund_id | B1: month_end | C1: redemptions | D1: redemptions_source | E1: distributions | F1: distributions_source | G1: aum | H1: aum_source | I1: sgg_nav | J1: sgg_nav_source | K1: nav | L1: nav_source | M1: nav_per_share | N1: nav_per_share_source | O1: distributions_per_share | P1: distributions_per_share_source | Q1: monthly_return | R1: monthly_return_source | S1: nport_portfolio_count | T1: gav | U1: gav_source | V1: shares_outstanding | W1: shares_outstanding_source | X1: shares_owned | Y1: shares_owned_source | Z1: sgg_purchases | AA1: sgg_purchases_source | AB1: sgg_redemptions | AC1: sgg_redemptions_source | AD1: sgg_distributions | AE1: sgg_distributions_source | AF1: gp_count | AG1: gp_count_source | AH1: fund_name | AI1: strategy
A2: 1 | B2: 43982 | M2: 26.04 | N2: pitchbook | AH2: =IFERROR(VLOOKUP($A2,fund_metadata!$A:$P,2,FALSE),"") -> Bow River Evergreen PE | AI2: =IFERROR(VLOOKUP($A2,fund_metadata!$A:$P,16,FALSE),"") -> private_equity
A3: 1 | B3: 44012 | M3: 28.71 | N3: pitchbook | Q3: 0.1024 | R3: pitchbook | AH3: =IFERROR(VLOOKUP($A3,fund_metadata!$A:$P,2,FALSE),"") -> Bow River Evergreen PE | AI3: =IFERROR(VLOOKUP($A3,fund_metadata!$A:$P,16,FALSE),"") -> private_equity
A4: 1 | B4: 44043 | M4: 28.78 | N4: pitchbook | Q4: 0.0026 | R4: pitchbook | AH4: =IFERROR(VLOOKUP($A4,fund_metadata!$A:$P,2,FALSE),"") -> Bow River Evergreen PE | AI4: =IFERROR(VLOOKUP($A4,fund_metadata!$A:$P,16,FALSE),"") -> private_equity
A5: 1 | B5: 44074 | M5: 28.83 | N5: pitchbook | Q5: 0.0016 | R5: pitchbook | AH5: =IFERROR(VLOOKUP($A5,fund_metadata!$A:$P,2,FALSE),"") -> Bow River Evergreen PE | AI5: =IFERROR(VLOOKUP($A5,fund_metadata!$A:$P,16,FALSE),"") -> private_equity
A6: 1 | B6: 44104 | M6: 29.26 | N6: pitchbook | Q6: 0.0149 | R6: pitchbook | AH6: =IFERROR(VLOOKUP($A6,fund_metadata!$A:$P,2,FALSE),"") -> Bow River Evergreen PE | AI6: =IFERROR(VLOOKUP($A6,fund_metadata!$A:$P,16,FALSE),"") -> private_equity
A7: 1 | B7: 44135 | M7: 29.26 | N7: pitchbook | Q7: 0.0001 | R7: pitchbook | AH7: =IFERROR(VLOOKUP($A7,fund_metadata!$A:$P,2,FALSE),"") -> Bow River Evergreen PE | AI7: =IFERROR(VLOOKUP($A7,fund_metadata!$A:$P,16,FALSE),"") -> private_equity
A8: 1 | B8: 44165 | M8: 29.6 | N8: pitchbook | Q8: 0.0118 | R8: pitchbook | AH8: =IFERROR(VLOOKUP($A8,fund_metadata!$A:$P,2,FALSE),"") -> Bow River Evergreen PE | AI8: =IFERROR(VLOOKUP($A8,fund_metadata!$A:$P,16,FALSE),"") -> private_equity
A9: 1 | B9: 44196 | M9: 29.58 | N9: pitchbook | Q9: -0.0008 | R9: pitchbook | AH9: =IFERROR(VLOOKUP($A9,fund_metadata!$A:$P,2,FALSE),"") -> Bow River Evergreen PE | AI9: =IFERROR(VLOOKUP($A9,fund_metadata!$A:$P,16,FALSE),"") -> private_equity
A10: 1 | B10: 44227 | M10: 30.39 | N10: pitchbook | Q10: 0.0273 | R10: pitchbook | AH10: =IFERROR(VLOOKUP($A10,fund_metadata!$A:$P,2,FALSE),"") -> Bow River Evergreen PE | AI10: =IFERROR(VLOOKUP($A10,fund_metadata!$A:$P,16,FALSE),"") -> private_equity
A11: 1 | B11: 44255 | M11: 31.19 | N11: pitchbook | Q11: 0.0264 | R11: pitchbook | AH11: =IFERROR(VLOOKUP($A11,fund_metadata!$A:$P,2,FALSE),"") -> Bow River Evergreen PE | AI11: =IFERROR(VLOOKUP($A11,fund_metadata!$A:$P,16,FALSE),"") -> private_equity
A12: 1 | B12: 44286 | M12: 31.77 | N12: pitchbook | Q12: 0.0186 | R12: pitchbook | S12: 32 | V12: 2869318 | W12: N-CSR | AH12: =IFERROR(VLOOKUP($A12,fund_metadata!$A:$P,2,FALSE),"") -> Bow River Evergreen PE | AI12: =IFERROR(VLOOKUP($A12,fund_metadata!$A:$P,16,FALSE),"") -> private_equity
A13: 1 | B13: 44316 | M13: 31.79 | N13: pitchbook | Q13: 0.0007 | R13: pitchbook | AH13: =IFERROR(VLOOKUP($A13,fund_metadata!$A:$P,2,FALSE),"") -> Bow River Evergreen PE | AI13: =IFERROR(VLOOKUP($A13,fund_metadata!$A:$P,16,FALSE),"") -> private_equity
A14: 1 | B14: 44347 | M14: 33.04 | N14: pitchbook | Q14: 0.0394 | R14: pitchbook | AH14: =IFERROR(VLOOKUP($A14,fund_metadata!$A:$P,2,FALSE),"") -> Bow River Evergreen PE | AI14: =IFERROR(VLOOKUP($A14,fund_metadata!$A:$P,16,FALSE),"") -> private_equity
A15: 1 | B15: 44377 | K15: 127850000 | L15: pitchbook | M15: 33.84 | N15: pitchbook | Q15: 0.0242 | R15: pitchbook | S15: 40 | AH15: =IFERROR(VLOOKUP($A15,fund_metadata!$A:$P,2,FALSE),"") -> Bow River Evergreen PE | AI15: =IFERROR(VLOOKUP($A15,fund_metadata!$A:$P,16,FALSE),"") -> private_equity
A16: 1 | B16: 44408 | K16: 131660000 | L16: pitchbook | M16: 34.52 | N16: pitchbook | Q16: 0.02 | R16: pitchbook | AH16: =IFERROR(VLOOKUP($A16,fund_metadata!$A:$P,2,FALSE),"") -> Bow River Evergreen PE | AI16: =IFERROR(VLOOKUP($A16,fund_metadata!$A:$P,16,FALSE),"") -> private_equity
A17: 1 | B17: 44439 | K17: 141200000 | L17: pitchbook | M17: 36.01 | N17: pitchbook | Q17: 0.0432 | R17: pitchbook | AH17: =IFERROR(VLOOKUP($A17,fund_metadata!$A:$P,2,FALSE),"") -> Bow River Evergreen PE | AI17: =IFERROR(VLOOKUP($A17,fund_metadata!$A:$P,16,FALSE),"") -> private_equity
A18: 1 | B18: 44469 | K18: 150110000 | L18: pitchbook | M18: 36.75 | N18: pitchbook | Q18: 0.0204 | R18: pitchbook | S18: 46 | V18: 4085205 | W18: N-CSRS | AH18: =IFERROR(VLOOKUP($A18,fund_metadata!$A:$P,2,FALSE),"") -> Bow River Evergreen PE | AI18: =IFERROR(VLOOKUP($A18,fund_metadata!$A:$P,16,FALSE),"") -> private_equity
A19: 1 | B19: 44500 | K19: 152780000 | L19: pitchbook | M19: 36.76 | N19: pitchbook | Q19: 0.0004 | R19: pitchbook | AH19: =IFERROR(VLOOKUP($A19,fund_metadata!$A:$P,2,FALSE),"") -> Bow River Evergreen PE | AI19: =IFERROR(VLOOKUP($A19,fund_metadata!$A:$P,16,FALSE),"") -> private_equity
A20: 1 | B20: 44530 | K20: 172670000 | L20: pitchbook | M20: 38.41 | N20: pitchbook | Q20: 0.0449 | R20: pitchbook | AH20: =IFERROR(VLOOKUP($A20,fund_metadata!$A:$P,2,FALSE),"") -> Bow River Evergreen PE | AI20: =IFERROR(VLOOKUP($A20,fund_metadata!$A:$P,16,FALSE),"") -> private_equity
A21: 1 | B21: 44561 | K21: 181180000 | L21: pitchbook | M21: 38.38 | N21: pitchbook | Q21: 0.0063 | R21: pitchbook | S21: 53 | AH21: =IFERROR(VLOOKUP($A21,fund_metadata!$A:$P,2,FALSE),"") -> Bow River Evergreen PE | AI21: =IFERROR(VLOOKUP($A21,fund_metadata!$A:$P,16,FALSE),"") -> private_equity
A22: 1 | B22: 44592 | K22: 191620000 | L22: pitchbook | M22: 38.01 | N22: pitchbook | Q22: -0.0097 | R22: pitchbook | AH22: =IFERROR(VLOOKUP($A22,fund_metadata!$A:$P,2,FALSE),"") -> Bow River Evergreen PE | AI22: =IFERROR(VLOOKUP($A22,fund_metadata!$A:$P,16,FALSE),"") -> private_equity
A23: 1 | B23: 44620 | K23: 206170000 | L23: pitchbook | M23: 38.6 | N23: pitchbook | Q23: 0.0157 | R23: pitchbook | AH23: =IFERROR(VLOOKUP($A23,fund_metadata!$A:$P,2,FALSE),"") -> Bow River Evergreen PE | AI23: =IFERROR(VLOOKUP($A23,fund_metadata!$A:$P,16,FALSE),"") -> private_equity
A24: 1 | B24: 44651 | K24: 217280000 | L24: pitchbook | M24: 39.5 | N24: pitchbook | Q24: 0.0232 | R24: pitchbook | S24: 64 | T24: 230020000 | U24: pitchbook | V24: 5341595 | W24: N-CSR | AH24: =IFERROR(VLOOKUP($A24,fund_metadata!$A:$P,2,FALSE),"") -> Bow River Evergreen PE | AI24: =IFERROR(VLOOKUP($A24,fund_metadata!$A:$P,16,FALSE),"") -> private_equity
A25: 1 | B25: 44681 | K25: 227980000 | L25: pitchbook | M25: 39.68 | N25: pitchbook | Q25: 0.0045 | R25: pitchbook | AH25: =IFERROR(VLOOKUP($A25,fund_metadata!$A:$P,2,FALSE),"") -> Bow River Evergreen PE | AI25: =IFERROR(VLOOKUP($A25,fund_metadata!$A:$P,16,FALSE),"") -> private_equity
A26: 1 | B26: 44712 | K26: 238290000 | L26: pitchbook | M26: 40.13 | N26: pitchbook | Q26: 0.0114 | R26: pitchbook | AH26: =IFERROR(VLOOKUP($A26,fund_metadata!$A:$P,2,FALSE),"") -> Bow River Evergreen PE | AI26: =IFERROR(VLOOKUP($A26,fund_metadata!$A:$P,16,FALSE),"") -> private_equity
A27: 1 | B27: 44742 | K27: 247830000 | L27: pitchbook | M27: 39.92 | N27: pitchbook | Q27: -0.0053 | R27: pitchbook | S27: 79 | AH27: =IFERROR(VLOOKUP($A27,fund_metadata!$A:$P,2,FALSE),"") -> Bow River Evergreen PE | AI27: =IFERROR(VLOOKUP($A27,fund_metadata!$A:$P,16,FALSE),"") -> private_equity
A28: 1 | B28: 44773 | K28: 257890000 | L28: pitchbook | M28: 39.76 | N28: pitchbook | Q28: -0.0039 | R28: pitchbook | AH28: =IFERROR(VLOOKUP($A28,fund_metadata!$A:$P,2,FALSE),"") -> Bow River Evergreen PE | AI28: =IFERROR(VLOOKUP($A28,fund_metadata!$A:$P,16,FALSE),"") -> private_equity
A29: 1 | B29: 44804 | K29: 269150000 | L29: pitchbook | M29: 39.94 | N29: pitchbook | Q29: 0.0045 | R29: pitchbook | AH29: =IFERROR(VLOOKUP($A29,fund_metadata!$A:$P,2,FALSE),"") -> Bow River Evergreen PE | AI29: =IFERROR(VLOOKUP($A29,fund_metadata!$A:$P,16,FALSE),"") -> private_equity
A30: 1 | B30: 44834 | K30: 279610000 | L30: pitchbook | M30: 39.87 | N30: pitchbook | Q30: -0.0018 | R30: pitchbook | S30: 88 | T30: 292180000 | U30: pitchbook | V30: 6459606 | W30: N-CSRS | AH30: =IFERROR(VLOOKUP($A30,fund_metadata!$A:$P,2,FALSE),"") -> Bow River Evergreen PE | AI30: =IFERROR(VLOOKUP($A30,fund_metadata!$A:$P,16,FALSE),"") -> private_equity
A31: 1 | B31: 44865 | K31: 286020000 | L31: pitchbook | M31: 39.75 | N31: pitchbook | Q31: -0.003 | R31: pitchbook | AH31: =IFERROR(VLOOKUP($A31,fund_metadata!$A:$P,2,FALSE),"") -> Bow River Evergreen PE | AI31: =IFERROR(VLOOKUP($A31,fund_metadata!$A:$P,16,FALSE),"") -> private_equity
A32: 1 | B32: 44895 | K32: 296020000 | L32: pitchbook | M32: 40.18 | N32: pitchbook | Q32: 0.0107 | R32: pitchbook | AH32: =IFERROR(VLOOKUP($A32,fund_metadata!$A:$P,2,FALSE),"") -> Bow River Evergreen PE | AI32: =IFERROR(VLOOKUP($A32,fund_metadata!$A:$P,16,FALSE),"") -> private_equity
A33: 1 | B33: 44926 | K33: 299140000 | L33: pitchbook | M33: 39.39 | N33: pitchbook | Q33: 0.0081 | R33: pitchbook | S33: 96 | AH33: =IFERROR(VLOOKUP($A33,fund_metadata!$A:$P,2,FALSE),"") -> Bow River Evergreen PE | AI33: =IFERROR(VLOOKUP($A33,fund_metadata!$A:$P,16,FALSE),"") -> private_equity
A34: 1 | B34: 44957 | K34: 314370000 | L34: pitchbook | M34: 39.39 | N34: pitchbook | Q34: 0.0001 | R34: pitchbook | AH34: =IFERROR(VLOOKUP($A34,fund_metadata!$A:$P,2,FALSE),"") -> Bow River Evergreen PE | AI34: =IFERROR(VLOOKUP($A34,fund_metadata!$A:$P,16,FALSE),"") -> private_equity
A35: 1 | B35: 44985 | K35: 325700000 | L35: pitchbook | M35: 39.94 | N35: pitchbook | Q35: 0.0141 | R35: pitchbook | AH35: =IFERROR(VLOOKUP($A35,fund_metadata!$A:$P,2,FALSE),"") -> Bow River Evergreen PE | AI35: =IFERROR(VLOOKUP($A35,fund_metadata!$A:$P,16,FALSE),"") -> private_equity
A36: 1 | B36: 45016 | K36: 341380000 | L36: pitchbook | M36: 40.09 | N36: pitchbook | Q36: 0.0038 | R36: pitchbook | S36: 98 | T36: 353810000 | U36: pitchbook | AH36: =IFERROR(VLOOKUP($A36,fund_metadata!$A:$P,2,FALSE),"") -> Bow River Evergreen PE | AI36: =IFERROR(VLOOKUP($A36,fund_metadata!$A:$P,16,FALSE),"") -> private_equity
A37: 1 | B37: 45046 | K37: 352740000 | L37: pitchbook | M37: 40.41 | N37: pitchbook | Q37: 0.0078 | R37: pitchbook | AH37: =IFERROR(VLOOKUP($A37,fund_metadata!$A:$P,2,FALSE),"") -> Bow River Evergreen PE | AI37: =IFERROR(VLOOKUP($A37,fund_metadata!$A:$P,16,FALSE),"") -> private_equity
A38: 1 | B38: 45077 | K38: 357990000 | L38: pitchbook | M38: 40.41 | N38: pitchbook | Q38: 0.0002 | R38: pitchbook | AH38: =IFERROR(VLOOKUP($A38,fund_metadata!$A:$P,2,FALSE),"") -> Bow River Evergreen PE | AI38: =IFERROR(VLOOKUP($A38,fund_metadata!$A:$P,16,FALSE),"") -> private_equity
A39: 1 | B39: 45107 | K39: 369270000 | L39: pitchbook | M39: 40.69 | N39: pitchbook | Q39: 0.0068 | R39: pitchbook | S39: 98 | AH39: =IFERROR(VLOOKUP($A39,fund_metadata!$A:$P,2,FALSE),"") -> Bow River Evergreen PE | AI39: =IFERROR(VLOOKUP($A39,fund_metadata!$A:$P,16,FALSE),"") -> private_equity
A40: 1 | B40: 45138 | K40: 380550000 | L40: pitchbook | M40: 41.15 | N40: pitchbook | Q40: 0.0113 | R40: pitchbook | AH40: =IFERROR(VLOOKUP($A40,fund_metadata!$A:$P,2,FALSE),"") -> Bow River Evergreen PE | AI40: =IFERROR(VLOOKUP($A40,fund_metadata!$A:$P,16,FALSE),"") -> private_equity
...

Sheet pivot
B3: fund_id | C3: month_end | D3: monthly_return | E3: sgg_nav | F3: nav_per_share
B4: 1 | D4: 0.011815493 | E4: 20401211 | F4: 41.856438
B5: 2 | D5: 0.012669231 | E5: 10154379 | F5: 12.136
B6: 3 | D6: 0.0096465517 | E6: 38468270 | F6: 10.800667
B7: 4 | D7: 0.0131625 | E7: 30569224
B8: 5 | D8: 0.0070173913 | E8: 24655005 | F8: 10.1652
B9: 6 | D9: 0.014418182 | E9: 50253288 | F9: 47.998676
B10: 7 | D10: 0.021395238 | E10: 21528691 | F10: 39.979535
B11: 8 | D11: 0.0098515873 | E11: 39978754 | F11: 18.116614
B12: 9 | D12: 0.014194118 | E12: 40446746
B13: 10 | D13: 0.012490476 | E13: 40588235 | F13: 14.90375
B14: 11 | D14: 0.01225625 | E14: 40201307 | F14: 15.513333
B15: Grand Total | D15: 0.012266845 | E15: 3.5724511e+08 | F15: 24.993098

Sheet fund_metadata
A1: fund_id | B1: fund_name | C1: class_inception_date | D1: ticker | E1: cik | F1: share_class_count | G1: sec_name | H1: fund_type | I1: yfinance_link | J1: share_class | K1: direct_statement_name | L1: icapital_name | M1: ms_name | N1: website_link | O1: sgg_holding | P1: strategy | Q1: management_fee | R1: expense_ratio | S1: incentive_fee | T1: gate
A2: 1 | B2: Bow River Evergreen PE | C2: 44196 | D2: EVERX | E2: 1810256 | F2: 2 | G2: Bow River Capital Evergreen Fund | H2: Interval | I2: https://finance.yahoo.com/quote/EVERX/ | J2: Class I | K2: BOW RIVER CAP EVERGREEN FD CL I | N2: https://www.bowriverevergreen.com/ | O2: y | P2: private_equity | Q2: 0.0175 | R2: 0.0299 | T2: 0.05
A3: 2 | B3: Carlyle Alpinvest | C3: 45294 | D3: XCPIX | E3: 1899610 | F3: 4 | G3: Carlyle AlpInvest Private Markets Fund | H3: Tender | I3: https://finance.yahoo.com/quote/XCPIX/ | J3: Class I | K3: Carlyle Alphinvest Prvte Mrkts I | N3: https://www.carlyle.com/capm | O3: y | P3: private_equity | Q3: 0.0125 | R3: 0.0324 | S3: 0.1 | T3: 0.05
A4: 3 | B4: Cliffwater | C4: 44377 | D4: CELFX | E4: 1842754 | F4: 1 | G4: Cliffwater Enhanced Lending Fund | H4: Interval | I4: https://finance.yahoo.com/quote/CELFX/ | J4: Class I | K4: CLIFFWATER ENHANCED LENDING FUND CL I | N4: https://www.cliffwaterfunds.com/celfx | O4: y | P4: private_credit | Q4: 0.0095 | T4: 0.05
A5: 4 | B5: Coller Secondaries | C5: 45383 | E5: 1969180 | F5: 3 | G5: Coller Secondaries Private Equity Opportunities Fund | H5: Tender | J5: Class I | K5: Coller Secondaries Private Equity Opportunities Fund | N5: https://cspef.com/ | O5: y | P5: secondaries | Q5: 0.0165 | T5: 0.05
A6: 5 | B6: Stepstone PC Income | C6: 45446 | D6: CRDEX | E6: 2006100 | F6: 4 | G6: StepStone Private Credit Income Fund | H6: Interval | I6: https://finance.yahoo.com/quote/CRDEX/history/ | J6: Class I | K6: STEPSTONE PRIVATE CREDIT INCOME FD CL I | N6: https://www.stepstonegroup.com/what-we-do/solutions-services/private-wealth-solutions/crdex/ | O6: y | P6: private_credit | Q6: 0.0115 | T6: 0.05
A7: 6 | B7: Stepstone Private Markets | C7: 44105 | D7: XPMIX | E7: 1789470 | F7: 3 | G7: StepStone Private Markets | H7: Tender | I7: https://finance.yahoo.com/quote/XPMIX/ | J7: Class I | K7: STEPSTONE PRIVATE MARKETS I | N7: https://www.stepstonegroup.com/what-we-do/solutions-services/private-wealth-solutions/sprim/ | O7: y | P7: secondaries | Q7: 0.014 | T7: 0.05
A8: 7 | B8: Stepstone PV/Growth | C8: 44866 | D8: XSPIX | E8: 1918642 | F8: 3 | G8: StepStone Private Venture and Growth Fund | H8: Tender | I8: https://finance.yahoo.com/quote/XSPIX/ | J8: Class I | K8: STEPSTONE PRIVATE VENTURE AND GROWTH FD CL I | N8: https://www.stepstonegroup.com/what-we-do/solutions-services/private-wealth-solutions/spring/ | O8: y | P8: venture | Q8: 0.015 | T8: 0.025
A9: 8 | B9: AMG Pantheon | C9: 42304 | D9: XPEIX | E9: 1609211 | F9: 1 | G9: AMG Pantheon Fund, LLC | H9: Tender | J9: Class 3 | L9: AMG PANTHEON FUND CLASS 3 | M9: AMG PANTHEON FUND, LLC ESC | N9: https://www.pantheon.com/private-wealth-overview/amg-pantheon-fund/ | O9: y | P9: secondaries | Q9: 0.0125 | T9: 0.05
A10: 9 | B10: FLEX | C10: 45646 | E10: 2008602 | F10: 4 | G10: Franklin Lexington Private Markets Fund | H10: Tender | J10: Class I | M10: FLEX - CLASS I ESC | N10: https://www.flexpe.com | O10: y | P10: secondaries | Q10: 0.0125 | T10: 0.05
A11: 10 | B11: Hamilton Lane | C11: 44200 | D11: XHLIX | E11: 1803491 | F11: 3 | G11: Hamilton Lane Private Assets Fund | H11: Tender | I11: https://finance.yahoo.com/quote/XHLIX/ | J11: Class I | L11: HAMILTON LANE PVT ASSET FUND CL I | M11: HAMILTON LANE PAF (I) ESC | N11: https://www.hamiltonlane.com/en-us/strategies/evergreen/us-private-wealth/private-assets-fund | O11: y | P11: private_equity | Q11: 0.014 | R11: 0.0338 | S11: 0.1 | T11: 0.05
A12: 11 | B12: JPMF | C12: 45119 | E12: 1940499 | F12: 3 | G12: JPMorgan Private Markets Fund | H12: Tender | J12: Class I | L12: JPMORGAN PRIVATE MARKETS FUND - I | M12: JPMF CLASS I ESC | N12: https://am.jpmorgan.com/us/en/asset-management/adv/products/jpmorgan-private-markets-fund-i-48130f306 | O12: y | P12: private_equity | Q12: 0.01 | T12: 0.05

Sheet pitchbook_index
A1: month_end | B1: pitchbook_index
A2: 41820 | B2: 100
A3: 41851 | B3: 99.922618
A4: 41882 | B4: 100.48179
A5: 41912 | B5: 100.70548
A6: 41943 | B6: 101.05813
A7: 41973 | B7: 101.53131
A8: 42004 | B8: 100.99359
A9: 42035 | B9: 101.15965
A10: 42063 | B10: 102.68618
A11: 42094 | B11: 103.68794
A12: 42124 | B12: 104.06627
A13: 42155 | B13: 104.49655
... A139: 45991 | B139: 219.95068

Sheet stepstone_pm_index
A1: month_end | B1: steptone_pm_index
A2: 38807 | B2: 1000
A3: 38810 | B3: 1000.13
A4: 38811 | B4: 1001.46
A5: 38812 | B5: 1001.53
A6: 38813 | B6: 1001.25
A7: 38814 | B7: 1000.23
A8: 38817 | B8: 1000.16
A9: 38818 | B9: 1000.39
A10: 38819 | B10: 1000.26
A11: 38820 | B11: 1000.05
A12: 38824 | B12: 1001.82
A13: 38825 | B13: 1001.85
... A5026: 46175 | B5026: 7101.73

Sheet sp500_index
A1: month_end | B1: sp500_index
A2: 36556 | B2: 1394.46
A3: 36585 | B3: 1366.42
A4: 36616 | B4: 1498.58
A5: 36646 | B5: 1452.4301
A6: 36677 | B6: 1420.6
A7: 36707 | B7: 1454.6
A8: 36738 | B8: 1430.83
A9: 36769 | B9: 1517.6801
A10: 36799 | B10: 1436.51
A11: 36830 | B11: 1429.4
A12: 36860 | B12: 1314.95
A13: 36891 | B13: 1320.28
... A319: 46203 | B319: 7266.9902
